Workbook

Sheet Cover
C2: CHIPOTLE MEXICAN GRILL, INC.
C3: Discounted Cash Flow Analysis · NYSE: CMG
C5: DOCUMENT DETAILS
C6: Valuation date | E6: 46022
C7: Report date | E7: 46273
C8: Currency and units | E8: USD, $ in millions except per-share amounts and unit counts
C9: Prepared by | E9: Fedor Shcherbatenko Romanovich
C11: VALUATION SUMMARY
C12: Enterprise value | E12: =DCF!E63 -> 37871.623
C13: Equity value | E13: =DCF!E71 -> 39117.882
C14: Shares outstanding (mm) | E14: =DCF!E73 -> 1302.4
C15: Implied value per share | E15: =DCF!E74 -> 30.035229
C16: Market price at 31-Dec-2025 | E16: 37
C17: Implied downside | E17: =E15/E16-1 -> -0.18823706
C19: KEY ASSUMPTIONS
C20: WACC | E20: =Assumptions!E13 -> 0.0767218
C21: Terminal growth rate | E21: =Assumptions!E17 -> 0.025
C22: Effective tax rate | E22: =Assumptions!E16 -> 0.23575691
C23: Explicit forecast period (years) | E23: =Assumptions!E18 -> 5
C24: Terminal value as % of enterprise value | E24: =DCF!E62/DCF!E63 -> 0.82865117
C26: FORMATTING LEGEND
C27: Blue – a typed input. These are the cells to change when testing scenarios.
C28: Green – a direct link to a cell on another worksheet.
C29: Black – a formula calculated on the sheet where it sits. A formula that reaches another sheet but also does arithmetic stays black.
C30: Yellow fill – the live base case in a sensitivity grid, or an input still needing attention.
C33: CONTENTS
C34: Assumptions | E34: Every input and driver, with FY2025 actuals beside each forecast and a normalised terminal column
C35: Historicals | E35: FY2023–25 as reported, converted to $mm, with transcription checks against the filing
C36: DCF | E36: Operating build, free cash flow, discounting, terminal value, bridge to equity and sensitivity
C37: Sources | E37: Every figure traced to a primary filing, an official rate, or a documented judgement
C39: SOURCES
C40: Primary | E40: Chipotle Mexican Grill, Inc. Form 10-K for FY2025, filed 4-Feb-2026 – all historical financials, restaurant activity, comparable sales, balance sheet and share count
C41: Official | E41: US Department of the Treasury, Daily Treasury Par Yield Curve Rates – 10-year CMT at 31-Dec-2025
C42: Third-party | E42: Damodaran (NYU Stern) – industry unlevered beta corrected for cash, and US implied equity risk premium.
C43: Outstanding | E43: Market price at 31-Dec-2025 – WSJ Markets Data Home – historical prices, NYSE: CMG

Sheet Assumptions
C2: ASSUMPTIONS
C3: Chipotle Mexican Grill, Inc. · Valuation date 31-Dec-2025 · USD ($mm), except unit counts and per-share amounts
E5: Actual | F5: Forecast
E6: FY2025A | F6: Year 1 | G6: Year 2 | H6: Year 3 | I6: Year 4 | J6: Year 5 | K6: Terminal
C7: COST OF CAPITAL
C8: Risk-free rate (10-yr Treasury, 31-Dec-2025) | E8: 0.0418
C9: Equity beta | E9: 0.783
C10: Equity risk premium | E10: 0.0446
C11: Cost of equity | E11: =E8+E9*E10 -> 0.0767218
C12: Debt/total capitalisation | E12: 0
C13: WACC | E13: =E11 -> 0.0767218
C15: VALUATION ASSUMPTIONS
C16: Effective tax rate | E16: =Historicals!G44 -> 0.23575691
C17: Terminal Growth Rate | E17: 0.025
C18: Projection Period (Years) | E18: 5
C20: UNIT DRIVERS
C21: Restaurants, beginning | E21: 3726 | F21: =E24 -> 4042 | G21: =F24 -> 4373 | H21: =G24 -> 4703 | I21: =H24 -> 5031 | J21: =I24 -> 5358 | K21: =J24 -> 5683
C22: New openings | E22: 334 | F22: 350 | G22: 350 | H22: 350 | I22: 350 | J22: 350 | K22: =-K23 -> 26
C23: Closures | E23: -18 | F23: =-ROUND(F21*F26,0) -> -19 | G23: =-ROUND(G21*G26,0) -> -20 | H23: =-ROUND(H21*H26,0) -> -22 | I23: =-ROUND(I21*I26,0) -> -23 | J23: =-ROUND(J21*J26,0) -> -25 | K23: =-ROUND(K21*K26,0) -> -26
C24: Restaurants, ending | E24: =SUM(E21:E23) -> 4042 | F24: =SUM(F21:F23) -> 4373 | G24: =SUM(G21:G23) -> 4703 | H24: =SUM(H21:H23) -> 5031 | I24: =SUM(I21:I23) -> 5358 | J24: =SUM(J21:J23) -> 5683 | K24: =SUM(K21:K23) -> 5683
C25: Average restaurants | E25: =(E21+E24)/2 -> 3884 | F25: =(F21+F24)/2 -> 4207.5 | G25: =(G21+G24)/2 -> 4538 | H25: =(H21+H24)/2 -> 4867 | I25: =(I21+I24)/2 -> 5194.5 | J25: =(J21+J24)/2 -> 5520.5 | K25: =(K21+K24)/2 -> 5683
C26: Closure rate (% of beginning) | E26: =-E23/E21 -> 0.0048309179 | F26: 0.0046 | G26: 0.0046 | H26: 0.0046 | I26: 0.0046 | J26: 0.0046 | K26: 0.0046
C28: REVENUE DRIVERS
C29: Comparable restaurant sales growth | E29: -0.017 | F29: 0 | G29: 0.015 | H29: 0.02 | I29: 0.025 | J29: 0.025 | K29: =$E$17 -> 0.025
C30: Average unit volume ($mm) | E30: 3.104 | F30: =E30*(1+F29) -> 3.104 | G30: =F30*(1+G29) -> 3.15056 | H30: =G30*(1+H29) -> 3.2135712 | I30: =H30*(1+I29) -> 3.2939105 | J30: =I30*(1+J29) -> 3.3762582 | K30: =J30*(1+K29) -> 3.4606647
C32: COST DRIVERS (% of revenue)
C33: Food, beverage and packaging | E33: =Historicals!G13 -> 0.29574962 | F33: 0.2958 | G33: 0.296 | H33: 0.296 | I33: 0.296 | J33: 0.296 | K33: 0.296
C34: Labor | E34: =Historicals!G15 -> 0.25086199 | F34: 0.2509 | G34: 0.25 | H34: 0.25 | I34: 0.248 | J34: 0.247 | K34: 0.247
C35: Occupancy | E35: =Historicals!G17 -> 0.052399707 | F35: 0.0524 | G35: 0.052 | H35: 0.052 | I35: 0.0515 | J35: 0.051 | K35: 0.051
C36: Other operating costs | E36: =Historicals!G19 -> 0.14723149 | F36: 0.1472 | G36: 0.1465 | H36: 0.146 | I36: 0.145 | J36: 0.143 | K36: 0.143
C37: G&A | E37: =Historicals!G25 -> 0.054673723 | F37: 0.0547 | G37: 0.054 | H37: 0.054 | I37: 0.053 | J37: 0.052 | K37: 0.052
C38: Pre-opening costs | E38: =Historicals!G29 -> 0.0041513212 | F38: 0.0042 | G38: 0.0041 | H38: 0.004 | I38: 0.004 | J38: 0.004 | K38: 0.004
C39: Impairment, closure and disposals | E39: =Historicals!G31 -> 0.002306215 | F39: 0.0023 | G39: 0.0022 | H39: 0.0021 | I39: 0.002 | J39: 0.002 | K39: 0.002
C40: D&A | E40: =Historicals!G27 -> 0.030303043 | F40: 0.03 | G40: 0.03 | H40: 0.03 | I40: 0.03 | J40: 0.03 | K40: 0.03
C42: CAPITAL DRIVERS (% of revenue)
C43: Capital expenditures | E43: =Historicals!G48 -> 0.055874417 | F43: 0.055 | G43: 0.0545 | H43: 0.0543 | I43: 0.053 | J43: 0.051 | K43: 0.043
C44: Change in NWC | E44: =Historicals!G50 -> 0.056372886 | F44: 0 | G44: 0 | H44: 0 | I44: 0 | J44: 0 | K44: 0
C46: BRIDGE ITEMS
C47: Total debt | E47: 0
C48: Cash and cash equivalents | E48: 350.545
...

Sheet Historicals
C2: HISTORICAL FINANCIALS
C3: USD ($mm), fiscal years ended 31-Dec
C6: REPORTED ACTUALS
E8: FY2023 | F8: FY2024 | G8: FY2025
C9: Total Revenue | E9: 9871.649 | F9: 11313.853 | G9: 11925.601
C10: Revenue Growth | F10: =F9/E9-1 -> 0.14609555 | G10: =G9/F9-1 -> 0.054070704
C12: Food, beverage and packaging | E12: 2912.564 | F12: 3374.516 | G12: 3526.992
C13: % of revenue | E13: =E12/E9 -> 0.29504331 | F13: =F12/F9 -> 0.29826408 | G13: =G12/G9 -> 0.29574962
C14: Labor | E14: 2440.982 | F14: 2789.789 | G14: 2991.68
C15: % of revenue | E15: =E14/E9 -> 0.24727196 | F15: =F14/F9 -> 0.24658169 | G15: =G14/G9 -> 0.25086199
C16: Occupancy | E16: 503.264 | F16: 563.374 | G16: 624.898
C17: % of revenue | E17: =E16/E9 -> 0.050980743 | F17: =F16/F9 -> 0.049795061 | G17: =G16/G9 -> 0.052399707
C18: Other operating costs | E18: 1428.747 | F18: 1568.482 | G18: 1755.824
C19: % of revenue | E19: =E18/E9 -> 0.14473235 | F19: =F18/F9 -> 0.13863376 | G19: =G18/G9 -> 0.14723149
C21: Restaurant-level operating costs | E21: =E12+E14+E16+E18 -> 7285.557 | F21: =F12+F14+F16+F18 -> 8296.161 | G21: =G12+G14+G16+G18 -> 8899.394
C22: Restaurant-level margin | E22: =1-E21/E9 -> 0.26197163 | F22: =1-F21/F9 -> 0.2667254 | G22: =1-G21/G9 -> 0.25375719
C24: General and administrative expenses | E24: 633.584 | F24: 697.483 | G24: 652.017
C25: % of revenue | E25: =E24/E9 -> 0.064182185 | F25: =F24/F9 -> 0.061648582 | G25: =G24/G9 -> 0.054673723
C26: Depreciation and Amortization | E26: 319.394 | F26: 335.03 | G26: 361.382
C27: % of revenue | E27: =E26/E9 -> 0.032354675 | F27: =F26/F9 -> 0.02961237 | G27: =G26/G9 -> 0.030303043
C28: Pre-opening costs | E28: 36.931 | F28: 41.897 | G28: 49.507
C29: % of revenue | E29: =E28/E9 -> 0.0037411176 | F29: =F28/F9 -> 0.0037031593 | G29: =G28/G9 -> 0.0041513212
C30: Impairment, closure costs, and asset disposals | E30: 38.37 | F30: 26.949 | G30: 27.503
C31: % of revenue | E31: =E30/E9 -> 0.0038868886 | F31: =F30/F9 -> 0.0023819472 | G31: =G30/G9 -> 0.002306215
C33: Total operating expenses | E33: 8313.836 | F33: 9397.52 | G33: 9989.803
C35: Income from operations | E35: 1557.813 | F35: 1916.333 | G35: 1935.798
C36: Operating margin | E36: =E35/E9 -> 0.15780677 | F36: =F35/F9 -> 0.16937934 | G36: =G35/G9 -> 0.16232289
C38: EBITDA | E38: =E35+E26 -> 1877.207 | F38: =F35+F26 -> 2251.363 | G38: =G35+G26 -> 2297.18
C39: EBITDA margin | E39: =E38/E9 -> 0.19016144 | F39: =F38/F9 -> 0.19899171 | G39: =G38/G9 -> 0.19262593
C41: Interest and other income, net | E41: 62.693 | F41: 93.897 | G41: 73.721
C42: Income before income taxes | E42: 1620.506 | F42: 2010.23 | G42: 2009.519
C43: Provision for income taxes | E43: 391.769 | F43: 476.12 | G43: 473.758
C44: Effective tax rate | E44: =E43/E42 -> 0.2417572 | F44: =F43/F42 -> 0.23684852 | G44: =G43/G42 -> 0.23575691
C45: Net income | E45: 1228.737 | F45: 1534.11 | G45: 1535.761
C47: Capital expenditures | E47: 560.731 | F47: 593.603 | G47: 666.336
C48: % of revenue | E48: =E47/E9 -> 0.056802161 | F48: =F47/F9 -> 0.052466918 | G48: =G47/G9 -> 0.055874417
C49: Change in net working capital | E49: =E61 -> -47.158 | F49: =F61 -> -86.92 | G49: =G61 -> 34.486
C50: % of change in revenue | F50: =F49/(F9-E9) -> -0.060268866 | G50: =G49/(G9-F9) -> 0.056372886
C52: WORKING CAPITAL DERIVATION
C53: Accounts receivable | E53: -11.216 | F53: -29.274 | G53: -11.383
...

Sheet DCF
C2: DCF VALUATION
C3: Company Name: | E3: Chipotle Mexican Grill, Inc. (NYSE: CMG)
C4: Valuation Date: | E4: 46022
C5: Currency: | E5: USD ($mm), except per-share amounts
C7: KEY ASSUMPTIONS
C8: Discount Rate (WACC) | E8: =Assumptions!E13 -> 0.0767218
C9: Terminal Growth Rate | E9: =Assumptions!E17 -> 0.025
C10: Tax Rate | E10: =Assumptions!E16 -> 0.23575691
C11: Projection Period (Years) | E11: =Assumptions!E18 -> 5
C13: FINANCIAL PROJECTIONS
E15: FY2025A | F15: Year 1 | G15: Year 2 | H15: Year 3 | I15: Year 4 | J15: Year 5 | K15: Terminal
C16: Restaurants, average | E16: =Assumptions!E25 -> 3884 | F16: =Assumptions!F25 -> 4207.5 | G16: =Assumptions!G25 -> 4538 | H16: =Assumptions!H25 -> 4867 | I16: =Assumptions!I25 -> 5194.5 | J16: =Assumptions!J25 -> 5520.5 | K16: =Assumptions!K25 -> 5683
C17: Average unit volume ($mm) | E17: =Assumptions!E30 -> 3.104 | F17: =Assumptions!F30 -> 3.104 | G17: =Assumptions!G30 -> 3.15056 | H17: =Assumptions!H30 -> 3.2135712 | I17: =Assumptions!I30 -> 3.2939105 | J17: =Assumptions!J30 -> 3.3762582 | K17: =Assumptions!K30 -> 3.4606647
C18: Precalibration revenue (units ⨯AUV) | E18: =E16*E17 -> 12055.936 | F18: =F16*F17 -> 13060.08 | G18: =G16*G17 -> 14297.241 | H18: =H16*H17 -> 15640.451 | I18: =I16*I17 -> 17110.218 | J18: =J16*J17 -> 18638.634 | K18: =K16*K17 -> 19666.957
C19: Calibration factor | E19: =Historicals!G9/DCF!E18 -> 0.98918914 | F19: =$E$19 -> 0.98918914 | G19: =$E$19 -> 0.98918914 | H19: =$E$19 -> 0.98918914 | I19: =$E$19 -> 0.98918914 | J19: =$E$19 -> 0.98918914 | K19: =$E$19 -> 0.98918914
C20: Revenue | E20: =E18*E19 -> 11925.601 | F20: =F18*F19 -> 12918.889 | G20: =G18*G19 -> 14142.676 | H20: =H18*H19 -> 15471.364 | I20: =I18*I19 -> 16925.242 | J20: =J18*J19 -> 18437.134 | K20: =K18*K19 -> 19454.341
C21: Revenue growth | E21: =Historicals!G10 -> 0.054070704 | F21: =F20/E20-1 -> 0.083290422 | G21: =G20/F20-1 -> 0.094728461 | H21: =H20/G20-1 -> 0.093948876 | I21: =I20/H20-1 -> 0.093972159 | J21: =J20/I20-1 -> 0.089327654 | K21: =K20/J20-1 -> 0.055171633
C23: Food, beverage and packaging | E23: =-E20*Assumptions!E33 -> -3526.992 | F23: =-F20*Assumptions!F33 -> -3821.4075 | G23: =-G20*Assumptions!G33 -> -4186.2321 | H23: =-H20*Assumptions!H33 -> -4579.5238 | I23: =-I20*Assumptions!I33 -> -5009.8716 | J23: =-J20*Assumptions!J33 -> -5457.3917 | K23: =-K20*Assumptions!K33 -> -5758.4849
C24: Labor | E24: =-E20*Assumptions!E34 -> -2991.68 | F24: =-F20*Assumptions!F34 -> -3241.3493 | G24: =-G20*Assumptions!G34 -> -3535.669 | H24: =-H20*Assumptions!H34 -> -3867.8411 | I24: =-I20*Assumptions!I34 -> -4197.46 | J24: =-J20*Assumptions!J34 -> -4553.9721 | K24: =-K20*Assumptions!K34 -> -4805.2222
C25: Occupancy | E25: =-E20*Assumptions!E35 -> -624.898 | F25: =-F20*Assumptions!F35 -> -676.9498 | G25: =-G20*Assumptions!G35 -> -735.41914 | H25: =-H20*Assumptions!H35 -> -804.51095 | I25: =-I20*Assumptions!I35 -> -871.64996 | J25: =-J20*Assumptions!J35 -> -940.29384 | K25: =-K20*Assumptions!K35 -> -992.17138
C26: Other operating costs | E26: =-E20*Assumptions!E36 -> -1755.824 | F26: =-F20*Assumptions!F36 -> -1901.6605 | G26: =-G20*Assumptions!G36 -> -2071.902 | H26: =-H20*Assumptions!H36 -> -2258.8192 | I26: =-I20*Assumptions!I36 -> -2454.1601 | J26: =-J20*Assumptions!J36 -> -2636.5102 | K26: =-K20*Assumptions!K36 -> -2781.9707
C27: Restaurant-level operating costs | E27: =SUM(E23:E26) -> -8899.394 | F27: =SUM(F23:F26) -> -9641.3671 | G27: =SUM(G23:G26) -> -10529.222 | H27: =SUM(H23:H26) -> -11510.695 | I27: =SUM(I23:I26) -> -12533.142 | J27: =SUM(J23:J26) -> -13588.168 | K27: =SUM(K23:K26) -> -14337.849
C28: Restaurant-level profit | E28: =E20+E27 -> 3026.207 | F28: =F20+F27 -> 3277.5222 | G28: =G20+G27 -> 3613.4537 | H28: =H20+H27 -> 3960.6693 | I28: =I20+I27 -> 4392.1003 | J28: =J20+J27 -> 4848.9662 | K28: =K20+K27 -> 5116.4916
C29: Restaurant-level margin | E29: =E28/E20 -> 0.25375719 | F29: =F28/F20 -> 0.2537 | G29: =G28/G20 -> 0.2555 | H29: =H28/H20 -> 0.256 | I29: =I28/I20 -> 0.2595 | J29: =J28/J20 -> 0.263 | K29: =K28/K20 -> 0.263
C31: G&A | E31: =-E20*Assumptions!E37 -> -652.017 | F31: =-F20*Assumptions!F37 -> -706.66325 | G31: =-G20*Assumptions!G37 -> -763.7045 | H31: =-H20*Assumptions!H37 -> -835.45367 | I31: =-I20*Assumptions!I37 -> -897.03782 | J31: =-J20*Assumptions!J37 -> -958.73097 | K31: =-K20*Assumptions!K37 -> -1011.6257
C32: Pre-opening costs | E32: =-E20*Assumptions!E38 -> -49.507 | F32: =-F20*Assumptions!F38 -> -54.259335 | G32: =-G20*Assumptions!G38 -> -57.984971 | H32: =-H20*Assumptions!H38 -> -61.885457 | I32: =-I20*Assumptions!I38 -> -67.700967 | J32: =-J20*Assumptions!J38 -> -73.748536 | K32: =-K20*Assumptions!K38 -> -77.817363
C33: Impairment, closure and disposals | E33: =-E20*Assumptions!E39 -> -27.503 | F33: =-F20*Assumptions!F39 -> -29.713445 | G33: =-G20*Assumptions!G39 -> -31.113887 | H33: =-H20*Assumptions!H39 -> -32.489865 | I33: =-I20*Assumptions!I39 -> -33.850484 | J33: =-J20*Assumptions!J39 -> -36.874268 | K33: =-K20*Assumptions!K39 -> -38.908682
C34: EBITDA | E34: =E28+SUM(E31:E33) -> 2297.18 | F34: =F28+SUM(F31:F33) -> 2486.8862 | G34: =G28+SUM(G31:G33) -> 2760.6503 | H34: =H28+SUM(H31:H33) -> 3030.8403 | I34: =I28+SUM(I31:I33) -> 3393.511 | J34: =J28+SUM(J31:J33) -> 3779.6125 | K34: =K28+SUM(K31:K33) -> 3988.1399
C35: EBITDA margin | E35: =E34/E20 -> 0.19262593 | F35: =F34/F20 -> 0.1925 | G35: =G34/G20 -> 0.1952 | H35: =H34/H20 -> 0.1959 | I35: =I34/I20 -> 0.2005 | J35: =J34/J20 -> 0.205 | K35: =K34/K20 -> 0.205
C37: FREE CASH FLOW CALCULATION
C39: EBITDA | E39: =E34 -> 2297.18 | F39: =F34 -> 2486.8862 | G39: =G34 -> 2760.6503 | H39: =H34 -> 3030.8403 | I39: =I34 -> 3393.511 | J39: =J34 -> 3779.6125 | K39: =K34 -> 3988.1399
C40: Depreciation & Amortization | E40: =-E20*Assumptions!E40 -> -361.382 | F40: =-F20*Assumptions!F40 -> -387.56668 | G40: =-G20*Assumptions!G40 -> -424.28028 | H40: =-H20*Assumptions!H40 -> -464.14093 | I40: =-I20*Assumptions!I40 -> -507.75726 | J40: =-J20*Assumptions!J40 -> -553.11402 | K40: =-K20*Assumptions!K40 -> -583.63022
C41: EBIT | E41: =E39+E40 -> 1935.798 | F41: =F39+F40 -> 2099.3195 | G41: =G39+G40 -> 2336.3701 | H41: =H39+H40 -> 2566.6993 | I41: =I39+I40 -> 2885.7537 | J41: =J39+J40 -> 3226.4985 | K41: =K39+K40 -> 3404.5096
C42: Taxes on EBIT | E42: =-E41*$E$10 -> -456.37776 | F42: =-F41*$E$10 -> -494.92909 | G42: =-G41*$E$10 -> -550.8154 | H42: =-H41*$E$10 -> -605.11712 | I42: =-I41*$E$10 -> -680.3364 | J42: =-J41*$E$10 -> -760.66932 | K42: =-K41*$E$10 -> -802.63669
C43: NOPAT | E43: =E41+E42 -> 1479.4202 | F43: =F41+F42 -> 1604.3904 | G43: =G41+G42 -> 1785.5547 | H43: =H41+H42 -> 1961.5822 | I43: =I41+I42 -> 2205.4173 | J43: =J41+J42 -> 2465.8291 | K43: =K41+K42 -> 2601.873
C44: Add back: Depreciation & Amortization | E44: =-E40 -> 361.382 | F44: =-F40 -> 387.56668 | G44: =-G40 -> 424.28028 | H44: =-H40 -> 464.14093 | I44: =-I40 -> 507.75726 | J44: =-J40 -> 553.11402 | K44: =-K40 -> 583.63022
C45: Capital Expenditures | E45: =-E20*Assumptions!E43 -> -666.336 | F45: =-F20*Assumptions!F43 -> -710.53891 | G45: =-G20*Assumptions!G43 -> -770.77583 | H45: =-H20*Assumptions!H43 -> -840.09508 | I45: =-I20*Assumptions!I43 -> -897.03782 | J45: =-J20*Assumptions!J43 -> -940.29384 | K45: =-K20*Assumptions!K43 -> -836.53666
C46: Change in NWC | E46: =-Historicals!G49 -> -34.486 | F46: =-(F20-E20)*Assumptions!F44 -> 0 | G46: =-(G20-F20)*Assumptions!G44 -> 0 | H46: =-(H20-G20)*Assumptions!H44 -> 0 | I46: =-(I20-H20)*Assumptions!I44 -> 0 | J46: =-(J20-I20)*Assumptions!J44 -> 0 | K46: =-(K20-J20)*Assumptions!K44 -> 0
C47: Unlevered Free Cash Flow | E47: =SUM(E43:E46) -> 1139.9802 | F47: =SUM(F43:F46) -> 1281.4182 | G47: =SUM(G43:G46) -> 1439.0591 | H47: =SUM(H43:H46) -> 1585.6281 | I47: =SUM(I43:I46) -> 1816.1368 | J47: =SUM(J43:J46) -> 2078.6493 | K47: =SUM(K43:K46) -> 2348.9665
C49: DCF VALUATION
...

Sheet Sources
C2: SOURCES & ASSUMPTION RATIONALE
C3: Chipotle Mexican Grill, Inc. · Every input traced to a primary filing, an official rate, or a documented judgement
C5: SOURCES – HISTORICAL DATA
C6: Line Item | D6: Model Location | E6: Document | F6: Filing Date | G6: Location (Statement / Note / Page) | H6: Link | I6: Date Pulled | J6: Adjustment Notes
C7: Income statement – all lines | D7: =HYPERLINK("#'Historicals'!E9:G45","Historicals!E9:G45") -> Historicals!E9:G45 | E7: Chipotle Mexican Grill, Inc. Form 10-K, FY2025 | F7: 46057 | G7: Consolidated Statements of Income and Comprehensive Income, p. 37 | H7: =HYPERLINK("https://www.sec.gov/Archives/edgar/data/1058090/000105809026000009/cmg-20251231.htm","10-K FY2025 — EDGAR") -> 10-K FY2025 — EDGAR | I7: 46250 | J7: Converted from $000s as filed to $mm (÷1000). No other adjustment was made. EBITDA (row 38) is not a reported figure – it is calculated as income from operations + D&A.
C8: Capital Expenditures | D8: =HYPERLINK("#'Historicals'!E47:G47", "Historicals!E47:G47") -> Historicals!E47:G47 | E8: Chipotle Mexican Grill, Inc. Form 10-K, FY2025 | F8: 46057 | G8: Consolidated Statements of Cash Flows – investing activities, p. 39 | H8: =HYPERLINK("https://www.sec.gov/Archives/edgar/data/1058090/000105809026000009/cmg-20251231.htm","10-K FY2025 — EDGAR") -> 10-K FY2025 — EDGAR | I8: 46250 | J8: Cash capex per "Purchases of leasehold improvements, property and equipment". Excludes accrued unpaid capex.
C9: Change in net working capital | D9: =HYPERLINK("#'Historicals'!E53:G61", "Historicals!E53:G61") -> Historicals!E53:G61 | E9: Chipotle Mexican Grill, Inc. Form 10-K, FY2025 | F9: 46057 | G9: Consolidated Statements of Cash Flows – changes in operating assets and liabilities, p. 39 | H9: =HYPERLINK("https://www.sec.gov/Archives/edgar/data/1058090/000105809026000009/cmg-20251231.htm","10-K FY2025 — EDGAR") -> 10-K FY2025 — EDGAR | I9: 46250 | J9: Built from seven lines: accounts receivable, inventory, prepaid & other current assets, accounts payable, accrued payroll & benefits, accrued liabilities, unearned revenue. Sign flipped from the filing convention to present the cash use. Excluded – operating lease assets and operating lease liabilities, leases treated as operating expense; Income tax payable/receivable, tax modelled separately in FCF; Other assets and other long-term liabilities, not working capital related.
C10: Restaurant activity | D10: =HYPERLINK("#'Assumptions'!E21:E23","Assumptions!E21:E23") -> Assumptions!E21:E23 | E10: Chipotle Mexican Grill, Inc. Form 10-K, FY2025 | F10: 46057 | G10: MD&A, Restaurant Activity table, p. 24 | H10: =HYPERLINK("https://www.sec.gov/Archives/edgar/data/1058090/000105809026000009/cmg-20251231.htm","10-K FY2025 — EDGAR") -> 10-K FY2025 — EDGAR | I10: 46251 | J10: Company-owned only; partner-operated (14 at year end) excluded. Closures of 18 = 13 permanent + 5 relocations. Openings of 334 are gross. Roll-forward ties: 3,726 + 334 − 18 = 4,042
C11: Comparable sales & AUV | D11: =HYPERLINK("#'Assumptions'!E28:E29","Assumptions!E28:E29") -> Assumptions!E28:E29 | E11: Chipotle Mexican Grill, Inc. Form 10-K, FY2025 | F11: 46057 | G11: MD&A, Revenue table, p. 25 | H11: =HYPERLINK("https://www.sec.gov/Archives/edgar/data/1058090/000105809026000009/cmg-20251231.htm","10-K FY2025 — EDGAR") -> 10-K FY2025 — EDGAR | I11: 46251 | J11: Comps: (1.7%) = transactions (2.9%) + average check +1.2% (menu price +2.1%, check mix (0.9%)). AUV: $3.104m is trailing 12-month food and beverage revenue for restaurants open >12 full calendar months – a much narrower base than total revenue, from there goes the calibration factor
C12: FY2026 comparable sales guidance | D12: =HYPERLINK("#'Assumptions'!F28","Assumptions!F28") -> Assumptions!F28 | E12: Chipotle Mexican Grill, Inc. Form 10-K, FY2025 | F12: 46057 | G12: MD&A, p. 24 | H12: =HYPERLINK("https://www.sec.gov/Archives/edgar/data/1058090/000105809026000009/cmg-20251231.htm","10-K FY2025 — EDGAR") -> 10-K FY2025 — EDGAR | I12: 46251 | J12: Comparable sales guided "about flat"
C13: FY2026 opening guidance | D13: =HYPERLINK("#'Assumptions'!F22","Assumptions!F22") -> Assumptions!F22 | E13: Chipotle Mexican Grill, Inc. Form 10-K, FY2025 | F13: 46057 | G13: MD&A, p. 24 | H13: =HYPERLINK("https://www.sec.gov/Archives/edgar/data/1058090/000105809026000009/cmg-20251231.htm","10-K FY2025 — EDGAR") -> 10-K FY2025 — EDGAR | I13: 46251 | J13: 350 - 370 openings including 10 - 15 international partner-operated, so company-owned guidance is 340 - 355.
C14: Cash and investments | D14: =HYPERLINK("#'Assumptions'!E47:E49","Assumptions!E47:E49") -> Assumptions!E47:E49 | E14: Chipotle Mexican Grill, Inc. Form 10-K, FY2025 | F14: 46057 | G14: Consolidated Balance Sheets, p. 36 | H14: =HYPERLINK("https://www.sec.gov/Archives/edgar/data/1058090/000105809026000009/cmg-20251231.htm","10-K FY2025 — EDGAR") -> 10-K FY2025 — EDGAR | I14: 46251 | J14: Restricted cash of 35,364 excluded
C15: Total debt | D15: =HYPERLINK("#'Assumptions'!E46","Assumptions!E46") -> Assumptions!E46 | E15: Chipotle Mexican Grill, Inc. Form 10-K, FY2025 | F15: 46057 | G15: Balance Sheets p. 36; lease discount-rate note p. 41 | H15: =HYPERLINK("https://www.sec.gov/Archives/edgar/data/1058090/000105809026000009/cmg-20251231.htm","10-K FY2025 — EDGAR") -> 10-K FY2025 — EDGAR | I15: 46251 | J15: No borrowings line exists on the balance sheet. Filing states "we have no outstanding debt." $500.0mm revolving facility undrawn at year end
C16: Shares outstanding | D16: =HYPERLINK("#'Assumptions'!E51","Assumptions!E51") -> Assumptions!E51 | E16: Chipotle Mexican Grill, Inc. Form 10-K, FY2025 | F16: 46057 | G16: Cover page | H16: =HYPERLINK("https://www.sec.gov/Archives/edgar/data/1058090/000105809026000009/cmg-20251231.htm","10-K FY2025 — EDGAR") -> 10-K FY2025 — EDGAR | I16: 46251 | J16: Scale confirmed against basic EPS of $1.15 on net income of $1,535.8m, implying ~1,337.3m weighted-average shares, matching the income statement. Actual count used, not weighted average
C22: SOURCES – MARKET & THIRD-PARTY DATA
C23: Input | D23: Value | E23: Model location | F23: Source | G23: Detail | H23: Link | I23: Date Pulled | J23: Notes
C24: Risk-free rate | D24: 0.0418 | E24: =HYPERLINK("#'Assumptions'!E8","Assumptions!E8") -> Assumptions!E8 | F24: US Dept of the Treasury, Daily Treasury Par Yield Curve Rates | G24: 10-yr CMT, 31-Dec-2025. Same date: 20-yr 4.79%, 30-yr 4.84% | H24: Treasury par yield curve 2025 — CSV | I24: 46251 | J24: Official primary source. Yield taken as at the valuation date of 31-Dec-2025, not a period average. The published daily series is a permanent archive and is not overwritten.
C25: Equity beta | D25: 0.783 | E25: =HYPERLINK("#'Assumptions'!E9","Assumptions!E9") -> Assumptions!E9 | F25: Damodaran, Betas by Sector (US) – betas.xls | G25: Sheet "Industry Averages", row Restaurant/Dining, column "Unlevered beta corrected for cash". 64 US firms. File "Date updated": 5-Jan-2026. | H25: Damodaran betas.xls | I25: 46251 | J25: Third-party academic source, not a filing. Column choice follows the file's own note: "if you are looking for a pure-play beta, i.e., a beta for a business, the unlevered beta corrected for cash is your best bet." Damodaran overwrites this file at each annual update, so the URL will serve a different figure in future. Version is pinned by the internal "Date updated" of 5-Jan-2026
C26: Share price at valuation date | D26: 37 | E26: =HYPERLINK("#'Cover'!E16","Cover!E16") -> Cover!E16 | F26: WSJ Markets – historical prices, NYSE: CMG | G26: Closing price, 31-Dec-2025. | H26: WallStreetJournal.MarketDataHome | I26: 46251 | J26: Market data, not a primary filing. Comparator only – no valuation output depends on this figure
C27: Equity risk premium | D27: 0.0446 | E27: =HYPERLINK("#'Assumptions'!E10","Assumptions!E10") -> Assumptions!E10 | F27: Damodaran, Country Default Spreads and Risk Premiums – ctryprem.xlsx | G27: Sheet "ERPs by country", row United States, Total Equity Risk Premium. File "Date of update": 1-Jan-2026. Mature market premium 4.23% | H27: Damodaran ctryprem.xlsx | I27: 46251 | J27: Third-party academic source, not a filing. Implied, forward-looking premium, so it must be paired with the risk-free rate against which it was computed. The file states: "ERP for US = Implied Expected Return on US stocks - (US 10-yr T.Bond - Default spread for US)". File is overwritten at each update; version pinned by the internal date of 1-Jan-2026.
C32: SOURCES – ASSUMPTION RATIONALE
C33: Decision | D33: Value in model | E33: Rationale | F33: Anchor | G33: Date Set | H33: Model Location
C34: Leases treated as operating expense | D34: - | E34: Chipotle leases virtually all of its 4,042 restaurants. Rent is already deducted in the income statement, mainly within Occupancy, so EBITDA in the model is after rent. The lease liability of $5,075.8mm (Consolidated Balance Sheets, p. 36; total also shown in Note 9, p. 59) is therefore excluded from net debt, leaving net cash of $1,246.3mm. Why this choice: total lease cost was $671.1mm in FY2025 (Note 9, Leases – components of lease cost, p. 59), which exceeds the entire Occupancy line of $624.9mm (Consolidated Statements of Income, p. 37). The filing does not disclose how much lease cost sits in each expense line, so adding rent back to EBITDA would require an inaccurate estimate to take that split into account. This treatment requires no estimate. As a consequence EBITDA and enterprise value are not comparable to lease-capitalised EV/EBITDA multiples. | F34: Convention | G34: 46250 | H34: Assumptions!E46:E50
C35: WACC equals cost of equity | D35: 0.0767 | E35: Chipotle has no borrowings (Balance Sheets, p. 36; "we have no outstanding debt", p. 41), so in WACC = (E/V)·Re + (D/V)·Rd·(1−t) the debt is zero and E/V = 1. WACC therefore equals cost of equity. The 0.0% debt weight is entered explicitly in E12, so the reason the identity holds is visible. However that means no interest tax shield, so Chipotle's WACC is higher than an otherwise identical levered peer's purely from capital structure; and no relevering is required, since levered beta equals unlevered beta at D/E = 0. | F35: Convention | G35: 46251 | H35: Assumptions!E13
C36: Risk-free rate – maturity and date selection | D36: 0.0418 | E36: The 10-year yield is used to match the base against which Damodaran's implied ERP is computed. His premium is backed out of the S&P 500 against the 10-year T-bond, so pairing 4.46% with the 30-year yield of 4.84% would count the term premium twice and produce a cost of equity of 8.32% – above the implied total market return of 8.64%. The yield is taken as at the valuation date of 31-Dec-2025, consistent with the balance sheet, share count and both Damodaran files. | F36: Convention | G36: 46251 | H36: Assumptions!E8
C37: Equity beta – why an industry average | D37: 0.783 | E37: A 64-firm industry average is used, because bottom-up betas average out the standard error of any one regression and are the intended use of the source data. Limitation stated openly: a bottom-up beta assumes Chipotle carries average restaurant operating risk; as a higher-multiple, growth-dependent operator its own regression beta is likely higher. The current-year figure is used for date consistency with the 31-Dec-2025 valuation date, but the decline is monotonic and the average is materially higher, so beta is carried as an axis of the sensitivity analysis | F37: Peers | G37: 46251 | H37: Assumptions!E9
C38: Equity beta – why the unlevered, cash-corrected figure | D38: 0.783 | E38: Two sequential corrections to the industry average, for two unrelated distortions. (1) Leverage. The as-reported industry beta of 0.9241 embeds the peer group's 27.22% D/E, which Chipotle does not have. Unlevering: 0.9241 / [1 + (1 - 0.25) x 0.2722] = 0.7674. Relevering to Chipotle's D/E of zero leaves it unchanged, so levered beta equals unlevered beta. Using the as-reported average would import peer leverage into a debt-free company. (2) Cash. A measured beta is a blend of everything the company owns, and cash carries a beta of approximately zero, so it drags the measured figure down. With cash at 1.99% of firm value: 0.7674 / (1 - 0.0199) = 0.7830. The correction raises the beta, because removing the riskless component leaves a riskier remainder. The cash-corrected figure is required here because the DCF values operating assets only – cash and investments of $1,246.3mm are added separately in the bridge – so a cash-inclusive beta would understate operating risk and double-count the cash. The source file states the same: "if you are looking for a pure-play beta, i.e., a beta for a business, the unlevered beta corrected for cash is your best bet." | F38: Convention | G38: 46251 | H38: Assumptions!E9
C39: Equity risk premium – US, not mature-market | D39: 0.0446 | E39: The US-specific implied premium is used because Chipotle operates only in the US and Canada; the mature-market figure of 4.23% is the US premium net of the US sovereign default spread and would understate the premium for a US-domiciled operator. | F39: Third party academic | G39: 46251 | H39: Assumptions!E10
C40: Projection period | D40: 5 years | E40: Five explicit years with a normalised terminal year. Years 6–10 of a longer model would be unexamined extrapolation; a shorter horizon with an explicitly normalised terminal year is more defensible. Terminal value share of EV is at ~80% | F40: Convention | G40: 46251 | H40: Assumptions!E18
C41: Terminal growth rate | D41: 0.025 | E41: At steady state unit growth is zero – the 7,000-restaurant goal for the U.S. and Canada (Item 1, p. 8) is finite. Perpetual growth must therefore come from price and mix on a fixed base. Menu price increases were +2.1% (FY2025) and +2.9% (FY2024), p. 25, demonstrating pricing at or above long-run inflation even while transactions fell 2.9%. 2.5% represents inflation-level pricing with no real volume or unit growth, and sits below long-run nominal GDP of ~4% | F41: Convergence | G41: 46251 | H41: Assumptions!E17
C42: Terminal capex | D42: 4.3% of revenue | E42: Sized to satisfy g = ROIC × reinvestment rate. Capex per opening $2.00mm (666,336 ÷ 334 openings, p. 39 / p. 24); unit EBITDA $0.788mm (AUV $3.104mm × 25.38% restaurant-level margin); post-tax return per new restaurant ~26.6%. At ~25% incremental ROIC, 2.5% growth requires reinvestment of 10% of NOPAT ≈ 1.2% of revenue above D&A of 3.03%. Setting terminal capex equal to D&A would imply perpetual growth funded by zero incremental capital | F42: Convergence | G42: 46251 | H42: Assumptions!K42
C43: New openings | D43: 350/yr | E43: FY2026 guidance of 350–370 includes 10–15 international partner-operated restaurants outside the company-owned base being modelled, implying ~340–355 company-owned. 350 held flat across the forecast; FY2025 actual was 334 and FY2024 was 304, so the openings pace is assumed to stay flat at ~350 | F43: Guidance | G43: 46251 | H43: Assumptions!F22:K22
C44: Closure rate | D44: 0.46% of beginning units | E44: Closures modelled as a rate, so they scale with the estate. FY2025: 18 of 3,726 = 0.48%; FY2024: 15 of 3,437 = 0.44%. Holding a flat 18 closures would imply the closure rate falling to 0.32% by Year 5 as the base grows, unstated assumption | F44: History | G44: 46251 | H44: Assumptions!E23:K23
C45: Comparable sales path | D45: 0.0 / 1.5 / 2.0 / 2.5 / 2.5% | E45: Year 1 from management guidance of "about flat" (p. 24). Years 2–5 assume a gradual recovery converging on the terminal rate by Year 4, so comps consist of pricing only by the end of the explicit period – no discontinuity at the terminal boundary. FY2025 comps of (1.7%) were driven by transactions (2.9%), so recovery is modelled as transactions ceasing to decline rather than as further price increases | F45: Guidance | G45: 46251 | H45: Assumptions!F28:K28
C46: Cost driver paths | D46: EBITDA margin 19.3% → 20.4% | E46: Each line anchored to its FY2025 actual in column E via a live link to Historicals. Food held flat (29.50–29.83% over three years; ~15bp ongoing tariff impact per p. 25, offset by pricing). Labor 25.09% → 24.7% and occupancy 5.24% → 5.0% on the basis that both deteriorated because AUV fell rather than because costs rose, and should releverage as comps recover. Pre-opening, impairment and D&A held flat. Implied outcome: EBITDA margin 19.26% → 20.40% and restaurant-level margin 25.38% → 26.20% by Year 5 – a recovery to the FY2023 level, below the FY2024 peak of 26.67% | F46: History | G46: 46252 | H46: Assumptions!E32:K39
C47: Change in NWC | D47: 0 | E47: FY2024 was (6.0%) of Δ revenue and FY2025 +5.6%, with no identifiable pattern and an absolute impact under 4% of EBITDA. Working capital is structurally negative (payables and accruals exceed receivables and inventory), a normal restaurant trait. Zero is treated as the honest estimate and documented as immaterial | F47: History | G47: 46252 | H47: Assumptions!E43:K43
C48: AUV calibration factor | D48: 0.989 | E48: Revenue is built as average restaurants × AUV, but AUV covers only restaurants open more or equal to 12 full calendar months and only food and beverage revenue, while the multiplication uses all average restaurants against total revenue. Testing on FY2025: 3,884 × 3.104 = 12,056 against actual 11,925.6, a 1.1% overstatement. A calibration factor is applied so the method reproduces the actual base year | F48: Convention | G48: 46252 | H48: Assumptions!E29
C49: No EBITDA add-backs | D49: - | E49: Stock-based compensation ($119.5m), pre-opening costs ($49.5m) and impairment/closure/disposals ($27.5m) are all left in. The test applied is recurrence: each appears in every reporting year (impairment 36.9 / 26.9 / 27.5), so each is a structural cost of operating and growing the estate. SBC in particular dilutes shareholders annually and is a real cost paid in equity, not cash. | F49: Convention | G49: 46252 | H49: Historicals!E38:G38
C50: Restricted cash excluded | D50: 35.4 excluded | E50: Restricted as to withdrawal or use (primarily insurance-related restricted trusts, p. 36/p. 48), therefore unavailable for general corporate purposes and excluded from the bridge by convention. | F50: Convention | G50: 46252 | H50: Assumptions!E47:E49
C51: Equity investments not added | D51: 105.3 not added | E51: Note 5 (p. 50) discloses total equity investments of $105.3m (equity method $28.2m, other investments $77.1m), but the note states the Hyphen and Nuro holdings are "included within long-term investments", which are already inside the $197.1m in the bridge. Adding the disclosed total would double-count them. | F51: Convention | G51: 46252 | H51: Assumptions!E49
...
